Traceback (most recent call last):
  File "/Library/Frameworks/Python.framework/Versions/3.10/lib/python3.10/site-packages/jupyter_cache/executors/utils.py", line 58, in single_nb_execution
    executenb(
  File "/Library/Frameworks/Python.framework/Versions/3.10/lib/python3.10/site-packages/nbclient/client.py", line 1319, in execute
    return NotebookClient(nb=nb, resources=resources, km=km, **kwargs).execute()
  File "/Library/Frameworks/Python.framework/Versions/3.10/lib/python3.10/site-packages/jupyter_core/utils/__init__.py", line 165, in wrapped
    return loop.run_until_complete(inner)
  File "/Library/Frameworks/Python.framework/Versions/3.10/lib/python3.10/asyncio/base_events.py", line 641, in run_until_complete
    return future.result()
  File "/Library/Frameworks/Python.framework/Versions/3.10/lib/python3.10/site-packages/nbclient/client.py", line 709, in async_execute
    await self.async_execute_cell(
  File "/Library/Frameworks/Python.framework/Versions/3.10/lib/python3.10/site-packages/nbclient/client.py", line 1062, in async_execute_cell
    await self._check_raise_for_error(cell, cell_index, exec_reply)
  File "/Library/Frameworks/Python.framework/Versions/3.10/lib/python3.10/site-packages/nbclient/client.py", line 918, in _check_raise_for_error
    raise CellExecutionError.from_cell_and_msg(cell, exec_reply_content)
nbclient.exceptions.CellExecutionError: An error occurred while executing the following cell:
------------------
import os
import urllib.request

def download_file_if_absent(url, filename, search_dirs):
    for directory in search_dirs:
        file_path = os.path.join(directory, filename)
        if os.path.exists(file_path):
            print(f"{filename} already exists in {file_path}")
            return file_path

    target_path = os.path.join(search_dirs[0], filename)
    try:
        with urllib.request.urlopen(url) as response, open(target_path, "wb") as out_file:
            out_file.write(response.read())
        print(f"Downloaded {filename} to {target_path}")
    except Exception as e:
        print(f"Failed to download {filename}. Error: {e}")
    return target_path

verdict_path = download_file_if_absent(
    url=(
         "https://raw.githubusercontent.com/rasbt/"
         "LLMs-from-scratch/main/ch02/01_main-chapter-code/"
         "the-verdict.txt"
    ),
    filename="the-verdict.txt",
    search_dirs="."
)

with open(verdict_path, "r", encoding="utf-8") as f: # added ../01_main-chapter-code/
    text = f.read()
------------------

----- stdout -----
Failed to download the-verdict.txt. Error: <urlopen error EOF occurred in violation of protocol (_ssl.c:997)>
------------------

[0;31m---------------------------------------------------------------------------[0m
[0;31mFileNotFoundError[0m                         Traceback (most recent call last)
Cell [0;32mIn[5], line 30[0m
[1;32m     18[0m     [38;5;28;01mreturn[39;00m target_path
[1;32m     20[0m verdict_path [38;5;241m=[39m download_file_if_absent(
[1;32m     21[0m     url[38;5;241m=[39m(
[1;32m     22[0m          [38;5;124m"[39m[38;5;124mhttps://raw.githubusercontent.com/rasbt/[39m[38;5;124m"[39m
[0;32m   (...)[0m
[1;32m     27[0m     search_dirs[38;5;241m=[39m[38;5;124m"[39m[38;5;124m.[39m[38;5;124m"[39m
[1;32m     28[0m )
[0;32m---> 30[0m [38;5;28;01mwith[39;00m [38;5;28;43mopen[39;49m[43m([49m[43mverdict_path[49m[43m,[49m[43m [49m[38;5;124;43m"[39;49m[38;5;124;43mr[39;49m[38;5;124;43m"[39;49m[43m,[49m[43m [49m[43mencoding[49m[38;5;241;43m=[39;49m[38;5;124;43m"[39;49m[38;5;124;43mutf-8[39;49m[38;5;124;43m"[39;49m[43m)[49m [38;5;28;01mas[39;00m f: [38;5;66;03m# added ../01_main-chapter-code/[39;00m
[1;32m     31[0m     text [38;5;241m=[39m f[38;5;241m.[39mread()

File [0;32m/Library/Frameworks/Python.framework/Versions/3.10/lib/python3.10/site-packages/IPython/core/interactiveshell.py:324[0m, in [0;36m_modified_open[0;34m(file, *args, **kwargs)[0m
[1;32m    317[0m [38;5;28;01mif[39;00m file [38;5;129;01min[39;00m {[38;5;241m0[39m, [38;5;241m1[39m, [38;5;241m2[39m}:
[1;32m    318[0m     [38;5;28;01mraise[39;00m [38;5;167;01mValueError[39;00m(
[1;32m    319[0m         [38;5;124mf[39m[38;5;124m"[39m[38;5;124mIPython won[39m[38;5;124m'[39m[38;5;124mt let you open fd=[39m[38;5;132;01m{[39;00mfile[38;5;132;01m}[39;00m[38;5;124m by default [39m[38;5;124m"[39m
[1;32m    320[0m         [38;5;124m"[39m[38;5;124mas it is likely to crash IPython. If you know what you are doing, [39m[38;5;124m"[39m
[1;32m    321[0m         [38;5;124m"[39m[38;5;124myou can use builtins[39m[38;5;124m'[39m[38;5;124m open.[39m[38;5;124m"[39m
[1;32m    322[0m     )
[0;32m--> 324[0m [38;5;28;01mreturn[39;00m [43mio_open[49m[43m([49m[43mfile[49m[43m,[49m[43m [49m[38;5;241;43m*[39;49m[43margs[49m[43m,[49m[43m [49m[38;5;241;43m*[39;49m[38;5;241;43m*[39;49m[43mkwargs[49m[43m)[49m

[0;31mFileNotFoundError[0m: [Errno 2] No such file or directory: './the-verdict.txt'

