Traceback (most recent call last):
  File "/Library/Frameworks/Python.framework/Versions/3.10/lib/python3.10/site-packages/jupyter_cache/executors/utils.py", line 58, in single_nb_execution
    executenb(
  File "/Library/Frameworks/Python.framework/Versions/3.10/lib/python3.10/site-packages/nbclient/client.py", line 1319, in execute
    return NotebookClient(nb=nb, resources=resources, km=km, **kwargs).execute()
  File "/Library/Frameworks/Python.framework/Versions/3.10/lib/python3.10/site-packages/jupyter_core/utils/__init__.py", line 165, in wrapped
    return loop.run_until_complete(inner)
  File "/Library/Frameworks/Python.framework/Versions/3.10/lib/python3.10/asyncio/base_events.py", line 641, in run_until_complete
    return future.result()
  File "/Library/Frameworks/Python.framework/Versions/3.10/lib/python3.10/site-packages/nbclient/client.py", line 709, in async_execute
    await self.async_execute_cell(
  File "/Library/Frameworks/Python.framework/Versions/3.10/lib/python3.10/site-packages/nbclient/client.py", line 1062, in async_execute_cell
    await self._check_raise_for_error(cell, cell_index, exec_reply)
  File "/Library/Frameworks/Python.framework/Versions/3.10/lib/python3.10/site-packages/nbclient/client.py", line 918, in _check_raise_for_error
    raise CellExecutionError.from_cell_and_msg(cell, exec_reply_content)
nbclient.exceptions.CellExecutionError: An error occurred while executing the following cell:
------------------
import torch

class NeuralNetwork(torch.nn.Module):
    def __init__(self, num_inputs, num_outputs):
        super().__init__()

        self.layers = torch.nn.Sequential(
                
            # 1st hidden layer
            torch.nn.Linear(num_inputs, 30),
            torch.nn.ReLU(),

            # 2nd hidden layer
            torch.nn.Linear(30, 20),
            torch.nn.ReLU(),

            # output layer
            torch.nn.Linear(20, num_outputs),
        )

    def forward(self, x):
        logits = self.layers(x)
        return logits
------------------


[0;31m---------------------------------------------------------------------------[0m
[0;31mModuleNotFoundError[0m                       Traceback (most recent call last)
Cell [0;32mIn[1], line 1[0m
[0;32m----> 1[0m [38;5;28;01mimport[39;00m[38;5;250m [39m[38;5;21;01mtorch[39;00m
[1;32m      3[0m [38;5;28;01mclass[39;00m[38;5;250m [39m[38;5;21;01mNeuralNetwork[39;00m(torch[38;5;241m.[39mnn[38;5;241m.[39mModule):
[1;32m      4[0m     [38;5;28;01mdef[39;00m[38;5;250m [39m[38;5;21m__init__[39m([38;5;28mself[39m, num_inputs, num_outputs):

[0;31mModuleNotFoundError[0m: No module named 'torch'

